<?xml version="1.0" ?>
<mujoco model="robot">
  
  <compiler angle="radian" meshdir="meshes" autolimits="true"/>
  
  
  <default>
    <joint limited="true" damping="0.1" armature="0.01"/> <!--frictionloss="0.01"/>-->
    <geom condim="4" contype="1" conaffinity="15" friction="0.9 0.2 0.2" solref="0.001 2"/>
    <motor ctrllimited="true"/>
    <equality solref="0.001 2"/>
  </default>
  <!--<option iterations="50" timestep="0.001" viscosity="1e-06" solver="PGS" gravity="0 0 -9.81">
    <flag frictionloss="enable"/>
  </option>-->

  <asset>
    <texture name="texplane" type="2d" builtin="checker" rgb1=".0 .0 .0" rgb2=".8 .8 .8" width="100" height="108"/>
    <material name="matplane" reflectance="0." texture="texplane" texrepeat="1 1" texuniform="true"/>
  </asset>
  
  <worldbody>
    
    
    <geom name="ground" type="plane" pos="0.001 0 0" quat="1 0 0 0" material="matplane" condim="1" conaffinity="15" size="0 0 1"/>
    <light directional="true" diffuse="0.6 0.6 0.6" specular="0.2 0.2 0.2" pos="0 0 4" dir="0 0 -1"/>
    <light directional="true" diffuse="0.4 0.4 0.4" specular="0.1 0.1 0.1" pos="0 0 5.0" dir="0 0 -1" castshadow="false"/>
    <body name="root" pos="0 0 1.0" quat="1 0 0 0">
      <joint name="root_x" type="slide" axis="1 0 0" limited="false"/>
      <joint name="root_y" type="slide" axis="0 1 0" limited="false"/>
      <joint name="root_z" type="slide" axis="0 0 1" limited="false"/>
      <joint name="root_ball" type="ball" limited="false"/>
      <site name="imu" size="0.01" pos="0 0 0"/>
      <geom type="box" rgba="0.615686 0.811765 0.929412 0.501961" size="0.1 0.1 0.1"/>
      
    
      <geom pos="0.0160579 0.0593235 0.0498109" quat="0 -2.32051e-08 1 -2.32051e-08" type="box" rgba="0.972549 0.529412 0.00392157 0.501961" size="0.1 0.1 0.1"/>
      
    
      <geom pos="0.000148008 0.0434136 0.0633109" quat="2.32051e-08 0 -4.64102e-08 -1" type="box" rgba="0.768627 0.886275 0.952941 0.501961" size="0.1 0.1 0.1"/>
      
    
      <geom pos="-0.0870555 0.0664737 -0.0301332" quat="0.379928 -0.596368 0.596368 -0.379928" type="box" rgba="0.917647 0.917647 0.917647 0.501961" size="0.1 0.1 0.1"/>
      
    
      <geom pos="-0.0766223 0.032495 -0.00775921" quat="0.596368 0.379928 -0.379928 -0.596368" type="box" rgba="0.768627 0.886275 0.952941 0.501961" size="0.1 0.1 0.1"/>
      
    
      <geom pos="0.0870988 0.0664737 -0.0302898" quat="0.379928 -0.596368 -0.596368 0.379928" type="box" rgba="0.917647 0.917647 0.917647 0.501961" size="0.1 0.1 0.1"/>
      
    
      <geom pos="0.0766657 0.032495 -0.00791584" quat="0.596368 0.379928 0.379928 0.596368" type="box" rgba="0.768627 0.886275 0.952941 0.501961" size="0.1 0.1 0.1"/>
      
    
      <geom pos="-0.0521972 0.0576546 -0.0517891" quat="-2.32051e-08 1 0 0" type="box" rgba="0.615686 0.811765 0.929412 0.501961" size="0.1 0.1 0.1"/>
      
    
      <geom pos="0.101188 0.070595 -0.0581391" quat="0.707107 0.707107 0 0" type="box" rgba="0.647059 0.647059 0.647059 0.501961" size="0.1 0.1 0.1"/>
      
    
      <geom pos="0.0339639 0.0573548 -0.267689" quat="-1 -4.64102e-08 0 0" type="box" rgba="0.917647 0.917647 0.917647 0.501961" size="0.1 0.1 0.1"/>
      
    
      <geom pos="-1.4863e-05 0.0326678 -0.267689" quat="-1 -4.64102e-08 0 0" type="box" rgba="0.972549 0.529412 0.00392157 0.501961" size="0.1 0.1 0.1"/>
      
    
      <geom pos="-1.4863e-05 0.0171678 -0.300689" quat="6.96153e-08 -1 0 0" type="box" rgba="0.615686 0.811765 0.929412 0.501961" size="0.1 0.1 0.1"/>
      
    
      <geom pos="-0.0608462 0.162768 -0.344553" quat="-0.707107 -0.707107 0 0" type="box" rgba="0.917647 0.917647 0.917647 0.501961" size="0.1 0.1 0.1"/>
      
    
      <geom pos="-0.0855332 0.162768 -0.378532" quat="-0.5 -0.5 0.5 -0.5" type="box" rgba="0.768627 0.886275 0.952941 0.501961" size="0.1 0.1 0.1"/>
      
    
      <geom pos="0.0608165 0.162768 -0.41251" quat="-0.707107 -0.707107 0 0" type="box" rgba="0.917647 0.917647 0.917647 0.501961" size="0.1 0.1 0.1"/>
      
    
      <geom pos="0.0855035 0.162768 -0.378532" quat="-0.5 -0.5 -0.5 0.5" type="box" rgba="0.768627 0.886275 0.952941 0.501961" size="0.1 0.1 0.1"/>
      
    
      <geom pos="-1.4863e-05 0.0326678 -0.267689" quat="6.96153e-08 -1 0 0" type="box" rgba="0.768627 0.886275 0.952941 0.501961" size="0.1 0.1 0.1"/>
      
    
      <geom pos="5.1467e-05 -0.0190049 -0.184989" quat="0 -2.32051e-08 -1 -2.32051e-08" type="box" rgba="0.615686 0.811765 0.929412 0.501961" size="0.1 0.1 0.1"/>
      
    
      <geom pos="0.0457081 0.070595 0.0448109" quat="0.707107 0.707107 0 0" type="box" rgba="0.647059 0.647059 0.647059 0.501961" size="0.1 0.1 0.1"/>
      
    
      <geom pos="-1.4862e-05 0.095595 0.00363456" quat="0.707107 0.707107 0 0" type="box" rgba="0.615686 0.811765 0.929412 0.501961" size="0.1 0.1 0.1"/>
      
    
      <geom pos="-1.4862e-05 0.101945 -0.0860179" quat="0.707107 0.707107 0 0" type="box" rgba="0.654902 0.584314 0.823529 0.501961" size="0.1 0.1 0.1"/>
      
    
      <body name="link_head_1_x4_1_inner_1" pos="0.000148008 0.0434136 0.0633109" quat="0 2.32051e-08 -1 6.96153e-08">
        
      
        <inertial pos="0.00202976 -0.0118633 -0.105521" quat="0.838901 -0.101396 -0.0688856 0.5303" mass="0.827332" diaginertia="0.00357088 0.00317042 0.00242602"/>
        
      
        <joint name="joint_head_1_x4_1_dof_x4" pos="0 0 0" axis="0 0 1" range="-0.1 0" actuatorfrcrange="-1.5 1.5"/>
        
      
        <geom type="box" rgba="0.972549 0.529412 0.00392157 0.501961" size="0.1 0.1 0.1"/>
        
      
        <geom pos="0.0105058 0.00467747 -0.0345" quat="-2.32051e-08 1 0 0" type="box" rgba="0.980392 0.713726 0.00392157 0.501961" size="0.1 0.1 0.1"/>
        
      
        <geom pos="-0.0153423 -0.0481844 -0.10559" quat="0.672498 0.672499 -0.218508 -0.218508" type="box" rgba="0.972549 0.529412 0.00392157 0.501961" size="0.1 0.1 0.1"/>
        
      
        <geom pos="-0.0202786 -0.0279111 -0.1215" quat="-0.672499 0.672498 -0.218508 0.218508" type="box" rgba="0.768627 0.886275 0.952941 0.501961" size="0.1 0.1 0.1"/>
        
      
        <geom pos="-0.0202786 -0.0279111 -0.1215" quat="-0.672498 -0.672499 0.218508 0.218508" type="box" rgba="0.972549 0.529412 0.00392157 0.501961" size="0.1 0.1 0.1"/>
        
      
        <geom pos="-0.00752685 0.00546858 -0.11474" quat="0.672499 -0.672498 0.218508 -0.218508" type="box" rgba="0.615686 0.811765 0.929412 0.501961" size="0.1 0.1 0.1"/>
        
      
        <geom pos="0.1069 -0.0191042 -0.148502" quat="0.337381 0.303779 -0.5962 -0.662147" type="box" rgba="0.615686 0.811765 0.929412 0.501961" size="0.1 0.1 0.1"/>
        
      
        <geom pos="0.051203 -0.095764 -0.148502" quat="0.337381 0.303779 -0.5962 -0.662147" type="box" rgba="0.615686 0.811765 0.929412 0.501961" size="0.1 0.1 0.1"/>
        
    
      </body>
      
    
      <body name="link_right_arm_1_x8_1_inner_1" pos="-0.0766223 0.032495 -0.00775921" quat="0.379928 -0.596368 0.596368 -0.379928">
        
      
        <inertial pos="5.74658e-05 -0.0157287 -0.0923329" quat="0.705112 -0.0547355 0.055379 0.704808" mass="0.917616" diaginertia="0.00229411 0.00183573 0.000730018"/>
        
      
        <joint name="joint_right_arm_1_x8_1_dof_x8" pos="0 0 0" axis="0 0 1" range="1.47 1.5" actuatorfrcrange="-6 6"/>
        
      
        <geom type="box" rgba="0.972549 0.529412 0.00392157 0.501961" size="0.1 0.1 0.1"/>
        
      
        <geom pos="0 0.0155 -0.033" quat="-2.32051e-08 1 0 0" type="box" rgba="0.917647 0.917647 0.917647 0.501961" size="0.1 0.1 0.1"/>
        
      
        <geom pos="-0.0129787 -0.033 -0.0700556" quat="0.707107 0.707107 0 0" type="box" rgba="0.917647 0.917647 0.917647 0.501961" size="0.1 0.1 0.1"/>
        
      
        <geom pos="0 -0.033 -0.11" quat="-0.707107 0.707107 0 0" type="box" rgba="0.768627 0.886275 0.952941 0.501961" size="0.1 0.1 0.1"/>
        
      
        <body name="link_right_arm_1_x8_2_inner_1" pos="0 -0.033 -0.11" quat="0.707107 0.707107 0 0">
          
        
          <inertial pos="-0.0143491 -0.228792 -0.0717893" quat="0.727446 0.648688 -0.17523 0.139001" mass="2.51025" diaginertia="0.0680865 0.0653997 0.00571534"/>
          
        
          <joint name="joint_right_arm_1_x8_2_dof_x8" pos="0 0 0" axis="0 0 1" range="1.8 1.83" actuatorfrcrange="-6 6"/>
          
        
          <geom type="box" rgba="0.972549 0.529412 0.00392157 0.501961" size="0.1 0.1 0.1"/>
          
        
          <geom pos="0 0.0155 -0.033" type="box" rgba="0.917647 0.917647 0.917647 0.501961" size="0.1 0.1 0.1"/>
          
        
          <geom pos="-0.036 0.0325 -0.0945" quat="0.5 -0.5 -0.5 -0.5" type="box" rgba="0.972549 0.529412 0.00392157 0.501961" size="0.1 0.1 0.1"/>
          
        
          <geom pos="0 0.0325 -0.0945" quat="0.5 -0.5 -0.5 -0.5" type="box" rgba="0.498039 0.498039 0.498039 0.501961" size="0.1 0.1 0.1"/>
          
        
          <geom pos="0.00995929 1.23147e-09 -0.08875" quat="-0.183013 0.183013 -0.683013 -0.683013" type="box" rgba="0.972549 0.529412 0.00392157 0.501961" size="0.1 0.1 0.1"/>
          
        
          <geom pos="-0.0371458 -0.150323 -0.0951615" quat="-0.353553 0.612372 0.612372 -0.353553" type="box" rgba="0.972549 0.529412 0.00392157 0.501961" size="0.1 0.1 0.1"/>
          
        
          <geom pos="-0.0281458 -0.1815 -0.11075" quat="-0.353553 0.612372 0.612372 -0.353553" type="box" rgba="0.498039 0.498039 0.498039 0.501961" size="0.1 0.1 0.1"/>
          
        
          <geom pos="5.79459e-09 -0.17 -0.0945" quat="-0.612372 -0.353553 -0.353553 -0.612372" type="box" rgba="0.972549 0.529412 0.00392157 0.501961" size="0.1 0.1 0.1"/>
          
        
          <geom pos="0.0101536 -0.246 -0.0702667" quat="0.353553 -0.353553 -0.612372 -0.612372" type="box" rgba="0.972549 0.529412 0.00392157 0.501961" size="0.1 0.1 0.1"/>
          
        
          <geom pos="0.00433014 -0.2595 -0.092" quat="0.353553 0.353553 -0.612372 0.612372" type="box" rgba="0.768627 0.886275 0.952941 0.501961" size="0.1 0.1 0.1"/>
          
        
          <geom pos="0.00433014 -0.2595 -0.092" quat="-0.353553 0.353553 0.612372 0.612372" type="box" rgba="0.972549 0.529412 0.00392157 0.501961" size="0.1 0.1 0.1"/>
          
        
          <geom pos="0.0148359 -0.294 -0.0966775" quat="-0.32102 0.32102 0.630037 0.630037" type="box" rgba="0.615686 0.811765 0.929412 0.501961" size="0.1 0.1 0.1"/>
          
        
          <geom pos="-0.00897072 -0.32159 -0.121329" quat="-0.453991 -1.98957e-08 0.891007 -4.03647e-08" type="box" rgba="0.972549 0.529412 0.00392157 0.501961" size="0.1 0.1 0.1"/>
          
        
          <geom pos="-0.0074006 -0.3375 -0.100523" quat="3.04306e-08 -0.453991 -6.10406e-08 -0.891007" type="box" rgba="0.768627 0.886275 0.952941 0.501961" size="0.1 0.1 0.1"/>
          
        
          <geom pos="-0.0074006 -0.3375 -0.100523" quat="0.453991 4.09655e-08 -0.891007 8.17165e-08" type="box" rgba="0.972549 0.529412 0.00392157 0.501961" size="0.1 0.1 0.1"/>
          
        
          <geom pos="0.0259791 -0.33074 -0.0877711" quat="-5.15004e-08 0.453991 1.02392e-07 0.891007" type="box" rgba="0.615686 0.811765 0.929412 0.501961" size="0.1 0.1 0.1"/>
          
        
          <geom pos="-0.0333098 -0.42144 -0.0648618" quat="-0.707107 -0.415627 -3.08568e-08 0.572061" type="box" rgba="0.615686 0.811765 0.929412 0.501961" size="0.1 0.1 0.1"/>
          
        
          <geom pos="-0.0248871 -0.450369 -0.0526365" quat="0.415627 -0.707107 0.572061 1.75821e-08" type="box" rgba="0.231373 0.380392 0.705882 0.501961" size="0.1 0.1 0.1"/>
          
        
          <geom pos="-0.0779239 -0.339786 0.0203623" quat="0.698401 -0.5 0.110616 0.5" type="box" rgba="0.917647 0.917647 0.917647 0.501961" size="0.1 0.1 0.1"/>
          
        
          <geom pos="-0.0769857 -0.369417 0.00205806" quat="8.27991e-09 -0.572061 -0.707107 -0.415627" type="box" rgba="0.647059 0.647059 0.647059 0.501961" size="0.1 0.1 0.1"/>
          
        
          <geom pos="-0.0981467 -0.395573 0.0311837" quat="8.27991e-09 -0.572061 -0.707107 -0.415627" type="box" rgba="0.647059 0.647059 0.647059 0.501961" size="0.1 0.1 0.1"/>
          
        
          <geom pos="-0.0226452 -0.469229 -0.0557222" quat="-0.5 -0.698401 -0.5 0.110616" type="box" rgba="0.917647 0.917647 0.917647 0.501961" size="0.1 0.1 0.1"/>
          
        
          <geom pos="-0.0445095 -0.445464 -0.0426416" quat="-0.415627 0.707107 -0.572061 -4.41316e-08" type="box" rgba="0.647059 0.647059 0.647059 0.501961" size="0.1 0.1 0.1"/>
          
        
          <geom pos="-0.0494902 -0.471621 -0.00176025" quat="-0.415627 0.707107 -0.572061 -4.41316e-08" type="box" rgba="0.647059 0.647059 0.647059 0.501961" size="0.1 0.1 0.1"/>
          
        
          <geom pos="-0.0787869 -0.404508 -0.038388" quat="0.415627 -0.707107 0.572061 1.75821e-08" type="box" rgba="0.647059 0.647059 0.647059 0.501961" size="0.1 0.1 0.1"/>
          
        
          <geom pos="-0.0367923 -0.352255 -0.063318" quat="-0.415627 0.707107 -0.572061 -1.55285e-08" type="box" rgba="0.972549 0.529412 0.00392157 0.501961" size="0.1 0.1 0.1"/>
          
        
          <geom pos="-0.0248438 -0.373061 -0.0526961" quat="-0.707107 -0.415627 -2.25378e-09 0.572061" type="box" rgba="0.768627 0.886275 0.952941 0.501961" size="0.1 0.1 0.1"/>
          
        
          <geom pos="-0.0248438 -0.373061 -0.0526961" quat="0.415627 -0.707107 0.572061 -1.1021e-08" type="box" rgba="0.972549 0.529412 0.00392157 0.501961" size="0.1 0.1 0.1"/>
          
        
          <geom pos="-0.041404 -0.401839 -0.0378607" quat="0.226367 0.094653 0.904597 0.348574" type="box" rgba="0.615686 0.811765 0.929412 0.501961" size="0.1 0.1 0.1"/>
          
        
          <geom pos="-0.0281458 -0.1815 -0.11075" quat="-0.612372 -0.353553 -0.353553 -0.612372" type="box" rgba="0.980392 0.713726 0.00392157 0.501961" size="0.1 0.1 0.1"/>
          
        
          <geom pos="0 0.0325 -0.0945" quat="0.5 0.5 -0.5 0.5" type="box" rgba="0.980392 0.713726 0.00392157 0.501961" size="0.1 0.1 0.1"/>
          
      
        </body>
        
    
      </body>
      
    
      <body name="link_left_arm_2_x8_1_inner_1" pos="0.0766657 0.032495 -0.00791584" quat="0.379928 -0.596368 -0.596368 0.379928">
        
      
        <inertial pos="5.74658e-05 -0.0157287 -0.0923329" quat="0.705112 -0.0547355 0.055379 0.704808" mass="0.917616" diaginertia="0.00229411 0.00183573 0.000730018"/>
        
      
        <joint name="joint_left_arm_2_x8_1_dof_x8" pos="0 0 0" axis="0 0 1" range="-1.23 -1.2" actuatorfrcrange="-6 6"/>
        
      
        <geom type="box" rgba="0.972549 0.529412 0.00392157 0.501961" size="0.1 0.1 0.1"/>
        
      
        <geom pos="0 0.0155 -0.033" quat="-2.32051e-08 1 0 0" type="box" rgba="0.917647 0.917647 0.917647 0.501961" size="0.1 0.1 0.1"/>
        
      
        <geom pos="-0.0129787 -0.033 -0.0700556" quat="0.707107 0.707107 0 0" type="box" rgba="0.917647 0.917647 0.917647 0.501961" size="0.1 0.1 0.1"/>
        
      
        <geom pos="0 -0.033 -0.11" quat="-0.707107 0.707107 0 0" type="box" rgba="0.768627 0.886275 0.952941 0.501961" size="0.1 0.1 0.1"/>
        
      
        <body name="link_left_arm_2_x8_2_inner_1" pos="0 -0.033 -0.11" quat="0.707107 0.707107 0 0">
          
        
          <inertial pos="-0.0082135 -0.228792 -0.110868" quat="0.625134 0.762538 0.0972429 -0.13523" mass="2.51025" diaginertia="0.0691227 0.0669264 0.00509173"/>
          
        
          <joint name="joint_left_arm_2_x8_2_dof_x8" pos="0 0 0" axis="0 0 1" range="-1.63 -1.6" actuatorfrcrange="-6 6"/>
          
        
          <geom type="box" rgba="0.972549 0.529412 0.00392157 0.501961" size="0.1 0.1 0.1"/>
          
        
          <geom pos="0 0.0155 -0.033" type="box" rgba="0.917647 0.917647 0.917647 0.501961" size="0.1 0.1 0.1"/>
          
        
          <geom pos="-0.036 0.0325 -0.0945" quat="0.5 -0.5 -0.5 -0.5" type="box" rgba="0.972549 0.529412 0.00392157 0.501961" size="0.1 0.1 0.1"/>
          
        
          <geom pos="0 0.0325 -0.0945" quat="0.5 -0.5 -0.5 -0.5" type="box" rgba="0.498039 0.498039 0.498039 0.501961" size="0.1 0.1 0.1"/>
          
        
          <geom pos="-0.00995929 6.97758e-10 -0.08875" quat="0.683013 -0.683013 0.183013 0.183013" type="box" rgba="0.972549 0.529412 0.00392157 0.501961" size="0.1 0.1 0.1"/>
          
        
          <geom pos="0.0191458 -0.150323 -0.126338" quat="-0.353553 -0.612372 -0.612372 -0.353553" type="box" rgba="0.972549 0.529412 0.00392157 0.501961" size="0.1 0.1 0.1"/>
          
        
          <geom pos="0.0281458 -0.1815 -0.11075" quat="-0.353553 -0.612372 -0.612372 -0.353553" type="box" rgba="0.498039 0.498039 0.498039 0.501961" size="0.1 0.1 0.1"/>
          
        
          <geom pos="3.54902e-09 -0.17 -0.0945" quat="0.612372 -0.353553 -0.353553 0.612372" type="box" rgba="0.972549 0.529412 0.00392157 0.501961" size="0.1 0.1 0.1"/>
          
        
          <geom pos="-0.0260635 -0.246 -0.0978234" quat="0.353553 -0.353553 0.612372 0.612372" type="box" rgba="0.972549 0.529412 0.00392157 0.501961" size="0.1 0.1 0.1"/>
          
        
          <geom pos="-0.00433012 -0.2595 -0.092" quat="0.353553 0.353553 0.612372 -0.612372" type="box" rgba="0.768627 0.886275 0.952941 0.501961" size="0.1 0.1 0.1"/>
          
        
          <geom pos="-0.00433012 -0.2595 -0.092" quat="-0.353553 0.353553 -0.612372 -0.612372" type="box" rgba="0.972549 0.529412 0.00392157 0.501961" size="0.1 0.1 0.1"/>
          
        
          <geom pos="-0.0055322 -0.294 -0.080563" quat="-0.385118 0.385118 -0.59303 -0.59303" type="box" rgba="0.615686 0.811765 0.929412 0.501961" size="0.1 0.1 0.1"/>
          
        
          <geom pos="0.0277203 -0.32159 -0.0888542" quat="-0.544639 -1.44742e-08 -0.838671 1.67367e-08" type="box" rgba="0.972549 0.529412 0.00392157 0.501961" size="0.1 0.1 0.1"/>
          
        
          <geom pos="0.00891628 -0.3375 -0.0978977" quat="2.71126e-08 -0.544639 3.61981e-08 0.838671" type="box" rgba="0.768627 0.886275 0.952941 0.501961" size="0.1 0.1 0.1"/>
          
        
          <geom pos="0.00891628 -0.3375 -0.0978977" quat="0.544639 3.9751e-08 0.838671 -5.56595e-08" type="box" rgba="0.972549 0.529412 0.00392157 0.501961" size="0.1 0.1 0.1"/>
          
        
          <geom pos="-0.0188169 -0.33074 -0.0753659" quat="-5.23894e-08 0.544639 -7.5121e-08 -0.838671" type="box" rgba="0.615686 0.811765 0.929412 0.501961" size="0.1 0.1 0.1"/>
          
        
          <geom pos="-0.00901247 -0.42144 -0.138166" quat="0.353553 0.703233 -0.612372 0.0739128" type="box" rgba="0.615686 0.811765 0.929412 0.501961" size="0.1 0.1 0.1"/>
          
        
          <geom pos="-0.0238113 -0.450369 -0.136985" quat="-0.703233 0.353553 0.0739128 0.612372" type="box" rgba="0.231373 0.380392 0.705882 0.501961" size="0.1 0.1 0.1"/>
          
        
          <geom pos="-0.0605117 -0.339786 -0.219415" quat="-0.444997 0.683013 0.549525 0.183013" type="box" rgba="0.917647 0.917647 0.917647 0.501961" size="0.1 0.1 0.1"/>
          
        
          <geom pos="-0.0451289 -0.369417 -0.209451" quat="0.612372 -0.0739128 0.353553 0.703233" type="box" rgba="0.647059 0.647059 0.647059 0.501961" size="0.1 0.1 0.1"/>
          
        
          <geom pos="-0.0597719 -0.395573 -0.242339" quat="0.612372 -0.0739128 0.353553 0.703233" type="box" rgba="0.647059 0.647059 0.647059 0.501961" size="0.1 0.1 0.1"/>
          
        
          <geom pos="-0.02226 -0.469229 -0.1335" quat="0.683013 0.444997 -0.183013 0.549525" type="box" rgba="0.917647 0.917647 0.917647 0.501961" size="0.1 0.1 0.1"/>
          
        
          <geom pos="-0.0226559 -0.445464 -0.158976" quat="0.703233 -0.353553 -0.0739128 -0.612372" type="box" rgba="0.647059 0.647059 0.647059 0.501961" size="0.1 0.1 0.1"/>
          
        
          <geom pos="-0.0555699 -0.471621 -0.18373" quat="0.703233 -0.353553 -0.0739128 -0.612372" type="box" rgba="0.647059 0.647059 0.647059 0.501961" size="0.1 0.1 0.1"/>
          
        
          <geom pos="-0.00920094 -0.404508 -0.190787" quat="-0.703233 0.353553 0.0739128 0.612372" type="box" rgba="0.647059 0.647059 0.647059 0.501961" size="0.1 0.1 0.1"/>
          
        
          <geom pos="-0.00860825 -0.352255 -0.141954" quat="0.703233 -0.353553 -0.0739128 -0.612372" type="box" rgba="0.972549 0.529412 0.00392157 0.501961" size="0.1 0.1 0.1"/>
          
        
          <geom pos="-0.0237813 -0.373061 -0.136917" quat="0.353553 0.703233 -0.612372 0.0739128" type="box" rgba="0.768627 0.886275 0.952941 0.501961" size="0.1 0.1 0.1"/>
          
        
          <geom pos="-0.0237813 -0.373061 -0.136917" quat="-0.703233 0.353553 0.0739128 0.612372" type="box" rgba="0.972549 0.529412 0.00392157 0.501961" size="0.1 0.1 0.1"/>
          
        
          <geom pos="-0.028349 -0.401839 -0.158677" quat="-0.896587 0.254547 -0.256259 -0.256259" type="box" rgba="0.615686 0.811765 0.929412 0.501961" size="0.1 0.1 0.1"/>
          
        
          <geom pos="0.0281458 -0.1815 -0.11075" quat="0.612372 -0.353553 -0.353553 0.612372" type="box" rgba="0.980392 0.713726 0.00392157 0.501961" size="0.1 0.1 0.1"/>
          
        
          <geom pos="0 0.0325 -0.0945" quat="0.5 0.5 -0.5 0.5" type="box" rgba="0.980392 0.713726 0.00392157 0.501961" size="0.1 0.1 0.1"/>
          
      
        </body>
        
    
      </body>
      
    
      <body name="link_legs_1_x8_1_inner_1" pos="-0.0855332 0.162768 -0.378532" quat="0.5 -0.5 -0.5 -0.5">
        
      
        <inertial pos="0.0140018 0.00808403 -0.0842001" quat="0.943137 0.00207075 -0.0740243 0.324051" mass="0.908312" diaginertia="0.00193332 0.00160535 0.000735299"/>
        
      
        <joint name="joint_legs_1_x8_1_dof_x8" pos="0 0 0" axis="0 0 1" range="-0.75 -0.15" actuatorfrcrange="-6 6"/>
        
      
        <geom type="box" rgba="0.972549 0.529412 0.00392157 0.501961" size="0.1 0.1 0.1"/>
        
      
        <geom pos="0.0134234 0.00775 -0.033" quat="-2.32051e-08 1 0 0" type="box" rgba="0.917647 0.917647 0.917647 0.501961" size="0.1 0.1 0.1"/>
        
      
        <geom pos="0.0115895 0.0459264 -0.073313" quat="0.353553 0.353553 0.612372 0.612372" type="box" rgba="0.917647 0.917647 0.917647 0.501961" size="0.1 0.1 0.1"/>
        
      
        <geom pos="0.0285788 0.0165 -0.098" quat="-0.353553 0.353553 0.612372 -0.612372" type="box" rgba="0.768627 0.886275 0.952941 0.501961" size="0.1 0.1 0.1"/>
        
      
        <body name="link_legs_1_right_leg_1_x8_1_inner_1" pos="0.0285788 0.0165 -0.098" quat="0.353553 0.353553 0.612372 0.612372">
          
        
          <inertial pos="-0.0381684 -0.0218296 -0.131938" quat="0.939524 -0.0480338 0.119492 0.317347" mass="1.31108" diaginertia="0.00531775 0.00452798 0.00167226"/>
          
        
          <joint name="joint_legs_1_right_leg_1_x8_1_dof_x8" pos="0 0 0" axis="0 0 1" range="-1 0" actuatorfrcrange="-6 6"/>
          
        
          <geom type="box" rgba="0.972549 0.529412 0.00392157 0.501961" size="0.1 0.1 0.1"/>
          
        
          <geom pos="0.0134234 -0.00775 -0.033" quat="-2.32051e-08 1 0 0" type="box" rgba="0.917647 0.917647 0.917647 0.501961" size="0.1 0.1 0.1"/>
          
        
          <geom pos="-0.0670252 -0.0199089 -0.099594" quat="-0.612372 0.612372 -0.353553 0.353553" type="box" rgba="0.972549 0.529412 0.00392157 0.501961" size="0.1 0.1 0.1"/>
          
        
          <geom pos="-0.0588363 -0.0340925 -0.15" quat="-0.683013 0.183013 -0.683013 -0.183013" type="box" rgba="0.498039 0.498039 0.498039 0.501961" size="0.1 0.1 0.1"/>
          
        
          <body name="link_legs_1_right_leg_1_x10_2_inner_1" pos="-0.0588363 -0.0340925 -0.15" quat="-0.183013 -0.683013 -0.183013 0.683013">
            
          
            <inertial pos="0.00071078 0.00685445 -0.0870115" quat="-0.280112 0.660187 0.0364271 0.695962" mass="1.64675" diaginertia="0.00394696 0.00350191 0.00324588"/>
            
          
            <joint name="joint_legs_1_right_leg_1_x10_2_dof_x10" pos="0 0 0" axis="0 0 1" range="-1.1 -0.4" actuatorfrcrange="-12 12"/>
            
          
            <geom type="box" rgba="0.980392 0.713726 0.00392157 0.501961" size="0.1 0.1 0.1"/>
            
          
            <geom pos="0 -0.018 -0.0405" quat="-2.32051e-08 1 0 0" type="box" rgba="0.647059 0.647059 0.647059 0.501961" size="0.1 0.1 0.1"/>
            
          
            <geom pos="0.00554001 -0.0527097 -0.118" quat="-0.866025 -4.01924e-08 0 -0.5" type="box" rgba="0.972549 0.529412 0.00392157 0.501961" size="0.1 0.1 0.1"/>
            
          
            <geom pos="-2.0548e-09 3.85337e-09 -0.118" quat="3.44263e-08 -0.258819 -0.965926 -6.00592e-09" type="box" rgba="0.980392 0.713726 0.00392157 0.501961" size="0.1 0.1 0.1"/>
            
          
            <geom pos="0.009 0.0155885 -0.0775" quat="0.258819 4.04322e-08 1.64085e-08 0.965926" type="box" rgba="0.917647 0.917647 0.917647 0.501961" size="0.1 0.1 0.1"/>
            
          
            <geom pos="-2.0548e-09 3.85337e-09 -0.118" quat="-0.258819 -2.84203e-08 2.84203e-08 -0.965926" type="box" rgba="0.498039 0.498039 0.498039 0.501961" size="0.1 0.1 0.1"/>
            
          
            <body name="link_legs_1_right_leg_1_51t_hdt5_15mm_belt_knee_right_1" pos="0.0906636 0.157034 -0.0795" quat="-0.866025 -4.01924e-08 0 -0.5">
              
            
              <inertial pos="0.0682772 -0.0369684 0.0351927" quat="0.988549 -0.108775 0.0379164 0.0974769" mass="0.643166" diaginertia="0.00188519 0.00174251 0.000550459"/>
              
            
              <joint name="joint_legs_1_right_leg_1_knee_revolute" pos="0 0 0" axis="0 0 -1" range="0 1.2" actuatorfrcrange="-13.9 13.9"/>
              
            
              <geom type="box" rgba="0.647059 0.647059 0.647059 0.501961" size="0.1 0.1 0.1"/>
              
            
              <geom pos="0.0393231 -0.032 0.0535" quat="-1.64085e-08 0.707107 0.707107 -1.64085e-08" type="box" rgba="0.972549 0.529412 0.00392157 0.501961" size="0.1 0.1 0.1"/>
              
            
              <geom pos="0.0705 -0.05 0.0535" quat="0.5 -8.49366e-09 -8.49366e-09 -0.866025" type="box" rgba="0.498039 0.498039 0.498039 0.501961" size="0.1 0.1 0.1"/>
              
            
              <geom pos="0.059 -0.05 0.021" quat="-3.10889e-09 0.5 -0.866025 2.85899e-08" type="box" rgba="0.972549 0.529412 0.00392157 0.501961" size="0.1 0.1 0.1"/>
              
            
              <geom pos="0.0705 -0.05 0.0535" quat="-2.00962e-08 -0.5 0.866025 1.16026e-08" type="box" rgba="0.980392 0.713726 0.00392157 0.501961" size="0.1 0.1 0.1"/>
              
            
              <body name="link_legs_1_right_leg_1_ankle_pulley_1" pos="0.24 -0.05 0" quat="0.707107 0 0 0.707107">
                
              
                <inertial pos="0.0583897 -0.0586158 0.011872" quat="0.190983 0.678427 -0.192074 0.682912" mass="0.219424" diaginertia="0.000467205 0.000423937 8.61629e-05"/>
                
              
                <joint name="joint_legs_1_right_leg_1_ankle_revolute" pos="0 0 0" axis="0 0 -1" range="-0.3 0.3" actuatorfrcrange="-6 6"/>
                
              
                <geom type="box" rgba="0.615686 0.811765 0.929412 0.501961" size="0.1 0.1 0.1"/>
                
              
                <geom pos="0 -0.0270536 0.002" quat="-2.32051e-08 1 0 0" type="box" rgba="0.647059 0.647059 0.647059 0.501961" size="0.1 0.1 0.1"/>
                
              
                <geom pos="0.0645536 -0.0663036 0.00154071" quat="0.5 0.5 0.5 0.5" type="box" rgba="0.972549 0.529412 0.00392157 0.501961" size="0.1 0.1 0.1"/>
                
              
                <body name="link_legs_1_right_leg_1_x4_1_outer_1" pos="0.0990536 -0.070981 0.0120465" quat="0.707107 3.53553e-08 0.707107 1.64085e-08">
                  
                
                  <inertial pos="1.40239e-09 -0.0149273 -0.046385" quat="0.924887 -0.380242 0 0" mass="0.390442" diaginertia="0.00139916 0.00114182 0.000664788"/>
                  
                
                  <joint name="joint_legs_1_right_leg_1_x4_1_dof_x4" pos="0 0 0" axis="0 0 -1" range="-0.3 0.3" actuatorfrcrange="-1.5 1.5"/>
                  
                
                  <geom type="box" rgba="0.768627 0.886275 0.952941 0.501961" size="0.1 0.1 0.1"/>
                  
                
                  <geom quat="-2.32051e-08 1 0 0" type="box" rgba="0.972549 0.529412 0.00392157 0.501961" size="0.1 0.1 0.1"/>
                  
                
                  <geom pos="-0.0159099 0.0159099 0.0135" quat="-1 -4.64102e-08 0 0" type="box" rgba="0.615686 0.811765 0.929412 0.501961" size="0.1 0.1 0.1"/>
                  
                
                  <geom pos="2e-09 -0.037 -0.0853793" quat="1.64085e-08 1.64085e-08 -0.707107 -0.707107" type="box" rgba="0.647059 0.647059 0.647059 0.501961" size="0.1 0.1 0.1"/>
                  
              
                </body>
                
            
              </body>
              
          
            </body>
            
        
          </body>
          
      
        </body>
        
    
      </body>
      
    
      <body name="link_legs_1_x8_2_inner_1" pos="0.0855035 0.162768 -0.378532" quat="0.5 -0.5 0.5 0.5">
        
      
        <inertial pos="-0.0140019 0.00808388 -0.0842001" quat="0.943137 0.00207089 0.0740242 -0.324052" mass="0.908312" diaginertia="0.00193332 0.00160535 0.000735299"/>
        
      
        <joint name="joint_legs_1_x8_2_dof_x8" pos="0 0 0" axis="0 0 1" range="0.2 0.75" actuatorfrcrange="-6 6"/>
        
      
        <geom type="box" rgba="0.972549 0.529412 0.00392157 0.501961" size="0.1 0.1 0.1"/>
        
      
        <geom pos="-0.0134234 0.00775 -0.033" quat="-2.32051e-08 1 0 0" type="box" rgba="0.917647 0.917647 0.917647 0.501961" size="0.1 0.1 0.1"/>
        
      
        <geom pos="-0.0455682 -0.0129264 -0.073313" quat="-0.353553 0.353553 -0.612372 0.612372" type="box" rgba="0.917647 0.917647 0.917647 0.501961" size="0.1 0.1 0.1"/>
        
      
        <geom pos="-0.0285788 0.0165 -0.098" quat="-0.353553 0.353553 -0.612372 0.612372" type="box" rgba="0.768627 0.886275 0.952941 0.501961" size="0.1 0.1 0.1"/>
        
      
        <body name="link_legs_1_left_leg_1_x8_1_inner_1" pos="-0.0285788 0.0165 -0.098" quat="-0.353553 -0.353553 0.612372 0.612372">
          
        
          <inertial pos="0.0379892 0.02214 -0.131938" quat="0.941093 0.0447332 -0.122919 0.311825" mass="1.31108" diaginertia="0.00532045 0.00453353 0.00166401"/>
          
        
          <joint name="joint_legs_1_left_leg_1_x8_1_dof_x8" pos="0 0 0" axis="0 0 1" range="-0.71 -0.3" actuatorfrcrange="-6 6"/>
          
        
          <geom type="box" rgba="0.972549 0.529412 0.00392157 0.501961" size="0.1 0.1 0.1"/>
          
        
          <geom pos="0 -0.0155 -0.033" quat="-2.32051e-08 1 0 0" type="box" rgba="0.917647 0.917647 0.917647 0.501961" size="0.1 0.1 0.1"/>
          
        
          <geom pos="0.0671321 0.0197238 -0.099594" quat="0.612372 0.612372 -0.353553 -0.353553" type="box" rgba="0.972549 0.529412 0.00392157 0.501961" size="0.1 0.1 0.1"/>
          
        
          <geom pos="0.0589432 0.0339075 -0.15" quat="0.183013 0.683013 0.183013 -0.683013" type="box" rgba="0.498039 0.498039 0.498039 0.501961" size="0.1 0.1 0.1"/>
          
        
          <body name="link_legs_1_left_leg_1_x10_1_inner_1" pos="0.0589432 0.0339075 -0.15" quat="-0.683013 0.183013 -0.683013 -0.183013">
            
          
            <inertial pos="0.000710775 -0.00685446 -0.0870115" quat="0.280115 0.660186 -0.036432 0.695962" mass="1.64675" diaginertia="0.00394696 0.0035019 0.00324588"/>
            
          
            <joint name="joint_legs_1_left_leg_1_x10_1_dof_x10" pos="0 0 0" axis="0 0 1" range="-0.1 1.2" actuatorfrcrange="-12 12"/>
            
          
            <geom type="box" rgba="0.980392 0.713726 0.00392157 0.501961" size="0.1 0.1 0.1"/>
            
          
            <geom pos="0.0155885 -0.009 -0.0405" quat="-2.32051e-08 1 0 0" type="box" rgba="0.647059 0.647059 0.647059 0.501961" size="0.1 0.1 0.1"/>
            
          
            <geom pos="0.00554001 0.0527097 -0.118" quat="-0.866025 -4.01924e-08 0 0.5" type="box" rgba="0.972549 0.529412 0.00392157 0.501961" size="0.1 0.1 0.1"/>
            
          
            <geom pos="-2.6548e-09 3.34021e-09 -0.118" quat="3.44263e-08 -0.258819 0.965926 6.00592e-09" type="box" rgba="0.980392 0.713726 0.00392157 0.501961" size="0.1 0.1 0.1"/>
            
          
            <geom pos="0.018 1.61837e-09 -0.0775" quat="0.258819 4.04322e-08 -1.64085e-08 -0.965926" type="box" rgba="0.917647 0.917647 0.917647 0.501961" size="0.1 0.1 0.1"/>
            
          
            <geom pos="-2.6548e-09 3.34021e-09 -0.118" quat="-0.258819 -2.84203e-08 -2.84203e-08 0.965926" type="box" rgba="0.498039 0.498039 0.498039 0.501961" size="0.1 0.1 0.1"/>
            
          
            <body name="link_legs_1_left_leg_1_51t_hdt5_15mm_belt_knee_left_1" pos="0.0906636 -0.157034 -0.0795" quat="-0.866025 -4.01924e-08 0 0.5">
              
            
              <inertial pos="0.0682779 0.0369688 0.0351927" quat="0.982089 -0.133732 -0.0379964 -0.127176" mass="0.643166" diaginertia="0.00188526 0.00177536 0.00051756"/>
              
            
              <joint name="joint_legs_1_left_leg_1_knee_revolute" pos="0 0 0" axis="0 0 -1" range="-1.2 0" actuatorfrcrange="-13.9 13.9"/>
              
            
              <geom type="box" rgba="0.647059 0.647059 0.647059 0.501961" size="0.1 0.1 0.1"/>
              
            
              <geom pos="0.0705 0.014 0.0535" quat="-1.64085e-08 0.707107 -0.707107 1.64085e-08" type="box" rgba="0.972549 0.529412 0.00392157 0.501961" size="0.1 0.1 0.1"/>
              
            
              <geom pos="0.0705 0.05 0.0535" quat="0.5 -8.49366e-09 8.49366e-09 0.866025" type="box" rgba="0.498039 0.498039 0.498039 0.501961" size="0.1 0.1 0.1"/>
              
            
              <geom pos="0.059 0.05 0.021" quat="-3.10889e-09 0.5 0.866025 -2.85899e-08" type="box" rgba="0.972549 0.529412 0.00392157 0.501961" size="0.1 0.1 0.1"/>
              
            
              <geom pos="0.0705 0.05 0.0535" quat="-2.00962e-08 -0.5 -0.866025 -1.16026e-08" type="box" rgba="0.980392 0.713726 0.00392157 0.501961" size="0.1 0.1 0.1"/>
              
            
              <body name="link_legs_1_left_leg_1_ankle_pulley_1" pos="0.24 0.05 0" quat="0.707107 0 0 -0.707107">
                
              
                <inertial pos="0.0583897 0.0586158 0.011128" quat="-0.192074 0.682912 0.190983 0.678427" mass="0.219424" diaginertia="0.000467205 0.000423937 8.61629e-05"/>
                
              
                <joint name="joint_legs_1_left_leg_1_ankle_revolute" pos="0 0 0" axis="0 0 -1" range="-0.3 0.3" actuatorfrcrange="-6 6"/>
                
              
                <geom type="box" rgba="0.615686 0.811765 0.929412 0.501961" size="0.1 0.1 0.1"/>
                
              
                <geom pos="0 0.0270536 0.021" type="box" rgba="0.647059 0.647059 0.647059 0.501961" size="0.1 0.1 0.1"/>
                
              
                <geom pos="0.0645536 0.0663036 0.0214593" quat="0.5 -0.5 0.5 -0.5" type="box" rgba="0.972549 0.529412 0.00392157 0.501961" size="0.1 0.1 0.1"/>
                
              
                <body name="link_legs_1_left_leg_1_x4_1_outer_1" pos="0.0990536 0.070981 0.0109535" quat="1.89469e-08 -0.707107 0 -0.707107">
                  
                
                  <inertial pos="1.40239e-09 -0.0149273 -0.046385" quat="0.924887 -0.380242 0 0" mass="0.390442" diaginertia="0.00139916 0.00114182 0.000664788"/>
                  
                
                  <joint name="joint_legs_1_left_leg_1_x4_1_dof_x4" pos="0 0 0" axis="0 0 -1" range="-0.3 0.3" actuatorfrcrange="-1.5 1.5"/>
                  
                
                  <geom type="box" rgba="0.768627 0.886275 0.952941 0.501961" size="0.1 0.1 0.1"/>
                  
                
                  <geom quat="-2.32051e-08 1 0 0" type="box" rgba="0.972549 0.529412 0.00392157 0.501961" size="0.1 0.1 0.1"/>
                  
                
                  <geom pos="-0.0159099 0.0159099 0.0135" quat="-1 -4.64102e-08 0 0" type="box" rgba="0.615686 0.811765 0.929412 0.501961" size="0.1 0.1 0.1"/>
                  
                
                  <geom pos="2e-09 -0.037 -0.0853793" quat="1.64085e-08 1.64085e-08 -0.707107 -0.707107" type="box" rgba="0.647059 0.647059 0.647059 0.501961" size="0.1 0.1 0.1"/>
                  
              
                </body>
                
            
              </body>
              
          
            </body>
            
        
          </body>
          
      
        </body>
        
    
      </body>
      
  
    </body>
  </worldbody>
  

  <actuator>
    <motor name="joint_head_1_x4_1_dof_x4" joint="joint_head_1_x4_1_dof_x4" ctrllimited="true" ctrlrange="-0.1 0.0" gear="1"/>
    <motor name="joint_right_arm_1_x8_1_dof_x8" joint="joint_right_arm_1_x8_1_dof_x8" ctrllimited="true" ctrlrange="1.47 1.5" gear="1"/>
    <motor name="joint_left_arm_2_x8_1_dof_x8" joint="joint_left_arm_2_x8_1_dof_x8" ctrllimited="true" ctrlrange="-1.23 -1.2" gear="1"/>
    <motor name="joint_right_arm_1_x8_2_dof_x8" joint="joint_right_arm_1_x8_2_dof_x8" ctrllimited="true" ctrlrange="1.8 1.83" gear="1"/>
    <motor name="joint_left_arm_2_x8_2_dof_x8" joint="joint_left_arm_2_x8_2_dof_x8" ctrllimited="true" ctrlrange="-1.63 -1.6" gear="1"/>
    <motor name="joint_legs_1_x8_1_dof_x8" joint="joint_legs_1_x8_1_dof_x8" ctrllimited="true" ctrlrange="-0.75 -0.15" gear="1"/>
    <motor name="joint_legs_1_x8_2_dof_x8" joint="joint_legs_1_x8_2_dof_x8" ctrllimited="true" ctrlrange="0.2 0.75" gear="1"/>
    <motor name="joint_legs_1_right_leg_1_x8_1_dof_x8" joint="joint_legs_1_right_leg_1_x8_1_dof_x8" ctrllimited="true" ctrlrange="-1 0.0" gear="1"/>
    <motor name="joint_legs_1_left_leg_1_x8_1_dof_x8" joint="joint_legs_1_left_leg_1_x8_1_dof_x8" ctrllimited="true" ctrlrange="-0.71 -0.3" gear="1"/>
    <motor name="joint_legs_1_right_leg_1_x10_2_dof_x10" joint="joint_legs_1_right_leg_1_x10_2_dof_x10" ctrllimited="true" ctrlrange="-1.1 -0.4" gear="1"/>
    <motor name="joint_legs_1_left_leg_1_x10_1_dof_x10" joint="joint_legs_1_left_leg_1_x10_1_dof_x10" ctrllimited="true" ctrlrange="-0.1 1.2" gear="1"/>
    <motor name="joint_legs_1_right_leg_1_knee_revolute" joint="joint_legs_1_right_leg_1_knee_revolute" ctrllimited="true" ctrlrange="0 1.2" gear="1"/>
    <motor name="joint_legs_1_left_leg_1_knee_revolute" joint="joint_legs_1_left_leg_1_knee_revolute" ctrllimited="true" ctrlrange="-1.2 0" gear="1"/>
    <motor name="joint_legs_1_right_leg_1_ankle_revolute" joint="joint_legs_1_right_leg_1_ankle_revolute" ctrllimited="true" ctrlrange="-0.3 0.3" gear="1"/>
    <motor name="joint_legs_1_left_leg_1_ankle_revolute" joint="joint_legs_1_left_leg_1_ankle_revolute" ctrllimited="true" ctrlrange="-0.3 0.3" gear="1"/>
    <motor name="joint_legs_1_right_leg_1_x4_1_dof_x4" joint="joint_legs_1_right_leg_1_x4_1_dof_x4" ctrllimited="true" ctrlrange="-0.3 0.3" gear="1"/>
    <motor name="joint_legs_1_left_leg_1_x4_1_dof_x4" joint="joint_legs_1_left_leg_1_x4_1_dof_x4" ctrllimited="true" ctrlrange="-0.3 0.3" gear="1"/>
  </actuator>
  <sensor>
    <actuatorpos name="joint_head_1_x4_1_dof_x4_p" actuator="joint_head_1_x4_1_dof_x4" user="13"/>
    <actuatorvel name="joint_head_1_x4_1_dof_x4_v" actuator="joint_head_1_x4_1_dof_x4" user="13"/>
    <actuatorfrc name="joint_head_1_x4_1_dof_x4_f" actuator="joint_head_1_x4_1_dof_x4" user="13" noise="0.001"/>
    <actuatorpos name="joint_right_arm_1_x8_1_dof_x8_p" actuator="joint_right_arm_1_x8_1_dof_x8" user="13"/>
    <actuatorvel name="joint_right_arm_1_x8_1_dof_x8_v" actuator="joint_right_arm_1_x8_1_dof_x8" user="13"/>
    <actuatorfrc name="joint_right_arm_1_x8_1_dof_x8_f" actuator="joint_right_arm_1_x8_1_dof_x8" user="13" noise="0.001"/>
    <actuatorpos name="joint_left_arm_2_x8_1_dof_x8_p" actuator="joint_left_arm_2_x8_1_dof_x8" user="13"/>
    <actuatorvel name="joint_left_arm_2_x8_1_dof_x8_v" actuator="joint_left_arm_2_x8_1_dof_x8" user="13"/>
    <actuatorfrc name="joint_left_arm_2_x8_1_dof_x8_f" actuator="joint_left_arm_2_x8_1_dof_x8" user="13" noise="0.001"/>
    <actuatorpos name="joint_right_arm_1_x8_2_dof_x8_p" actuator="joint_right_arm_1_x8_2_dof_x8" user="13"/>
    <actuatorvel name="joint_right_arm_1_x8_2_dof_x8_v" actuator="joint_right_arm_1_x8_2_dof_x8" user="13"/>
    <actuatorfrc name="joint_right_arm_1_x8_2_dof_x8_f" actuator="joint_right_arm_1_x8_2_dof_x8" user="13" noise="0.001"/>
    <actuatorpos name="joint_left_arm_2_x8_2_dof_x8_p" actuator="joint_left_arm_2_x8_2_dof_x8" user="13"/>
    <actuatorvel name="joint_left_arm_2_x8_2_dof_x8_v" actuator="joint_left_arm_2_x8_2_dof_x8" user="13"/>
    <actuatorfrc name="joint_left_arm_2_x8_2_dof_x8_f" actuator="joint_left_arm_2_x8_2_dof_x8" user="13" noise="0.001"/>
    <actuatorpos name="joint_legs_1_x8_1_dof_x8_p" actuator="joint_legs_1_x8_1_dof_x8" user="13"/>
    <actuatorvel name="joint_legs_1_x8_1_dof_x8_v" actuator="joint_legs_1_x8_1_dof_x8" user="13"/>
    <actuatorfrc name="joint_legs_1_x8_1_dof_x8_f" actuator="joint_legs_1_x8_1_dof_x8" user="13" noise="0.001"/>
    <actuatorpos name="joint_legs_1_x8_2_dof_x8_p" actuator="joint_legs_1_x8_2_dof_x8" user="13"/>
    <actuatorvel name="joint_legs_1_x8_2_dof_x8_v" actuator="joint_legs_1_x8_2_dof_x8" user="13"/>
    <actuatorfrc name="joint_legs_1_x8_2_dof_x8_f" actuator="joint_legs_1_x8_2_dof_x8" user="13" noise="0.001"/>
    <actuatorpos name="joint_legs_1_right_leg_1_x8_1_dof_x8_p" actuator="joint_legs_1_right_leg_1_x8_1_dof_x8" user="13"/>
    <actuatorvel name="joint_legs_1_right_leg_1_x8_1_dof_x8_v" actuator="joint_legs_1_right_leg_1_x8_1_dof_x8" user="13"/>
    <actuatorfrc name="joint_legs_1_right_leg_1_x8_1_dof_x8_f" actuator="joint_legs_1_right_leg_1_x8_1_dof_x8" user="13" noise="0.001"/>
    <actuatorpos name="joint_legs_1_left_leg_1_x8_1_dof_x8_p" actuator="joint_legs_1_left_leg_1_x8_1_dof_x8" user="13"/>
    <actuatorvel name="joint_legs_1_left_leg_1_x8_1_dof_x8_v" actuator="joint_legs_1_left_leg_1_x8_1_dof_x8" user="13"/>
    <actuatorfrc name="joint_legs_1_left_leg_1_x8_1_dof_x8_f" actuator="joint_legs_1_left_leg_1_x8_1_dof_x8" user="13" noise="0.001"/>
    <actuatorpos name="joint_legs_1_right_leg_1_x10_2_dof_x10_p" actuator="joint_legs_1_right_leg_1_x10_2_dof_x10" user="13"/>
    <actuatorvel name="joint_legs_1_right_leg_1_x10_2_dof_x10_v" actuator="joint_legs_1_right_leg_1_x10_2_dof_x10" user="13"/>
    <actuatorfrc name="joint_legs_1_right_leg_1_x10_2_dof_x10_f" actuator="joint_legs_1_right_leg_1_x10_2_dof_x10" user="13" noise="0.001"/>
    <actuatorpos name="joint_legs_1_left_leg_1_x10_1_dof_x10_p" actuator="joint_legs_1_left_leg_1_x10_1_dof_x10" user="13"/>
    <actuatorvel name="joint_legs_1_left_leg_1_x10_1_dof_x10_v" actuator="joint_legs_1_left_leg_1_x10_1_dof_x10" user="13"/>
    <actuatorfrc name="joint_legs_1_left_leg_1_x10_1_dof_x10_f" actuator="joint_legs_1_left_leg_1_x10_1_dof_x10" user="13" noise="0.001"/>
    <actuatorpos name="joint_legs_1_right_leg_1_knee_revolute_p" actuator="joint_legs_1_right_leg_1_knee_revolute" user="13"/>
    <actuatorvel name="joint_legs_1_right_leg_1_knee_revolute_v" actuator="joint_legs_1_right_leg_1_knee_revolute" user="13"/>
    <actuatorfrc name="joint_legs_1_right_leg_1_knee_revolute_f" actuator="joint_legs_1_right_leg_1_knee_revolute" user="13" noise="0.001"/>
    <actuatorpos name="joint_legs_1_left_leg_1_knee_revolute_p" actuator="joint_legs_1_left_leg_1_knee_revolute" user="13"/>
    <actuatorvel name="joint_legs_1_left_leg_1_knee_revolute_v" actuator="joint_legs_1_left_leg_1_knee_revolute" user="13"/>
    <actuatorfrc name="joint_legs_1_left_leg_1_knee_revolute_f" actuator="joint_legs_1_left_leg_1_knee_revolute" user="13" noise="0.001"/>
    <actuatorpos name="joint_legs_1_right_leg_1_ankle_revolute_p" actuator="joint_legs_1_right_leg_1_ankle_revolute" user="13"/>
    <actuatorvel name="joint_legs_1_right_leg_1_ankle_revolute_v" actuator="joint_legs_1_right_leg_1_ankle_revolute" user="13"/>
    <actuatorfrc name="joint_legs_1_right_leg_1_ankle_revolute_f" actuator="joint_legs_1_right_leg_1_ankle_revolute" user="13" noise="0.001"/>
    <actuatorpos name="joint_legs_1_left_leg_1_ankle_revolute_p" actuator="joint_legs_1_left_leg_1_ankle_revolute" user="13"/>
    <actuatorvel name="joint_legs_1_left_leg_1_ankle_revolute_v" actuator="joint_legs_1_left_leg_1_ankle_revolute" user="13"/>
    <actuatorfrc name="joint_legs_1_left_leg_1_ankle_revolute_f" actuator="joint_legs_1_left_leg_1_ankle_revolute" user="13" noise="0.001"/>
    <actuatorpos name="joint_legs_1_right_leg_1_x4_1_dof_x4_p" actuator="joint_legs_1_right_leg_1_x4_1_dof_x4" user="13"/>
    <actuatorvel name="joint_legs_1_right_leg_1_x4_1_dof_x4_v" actuator="joint_legs_1_right_leg_1_x4_1_dof_x4" user="13"/>
    <actuatorfrc name="joint_legs_1_right_leg_1_x4_1_dof_x4_f" actuator="joint_legs_1_right_leg_1_x4_1_dof_x4" user="13" noise="0.001"/>
    <actuatorpos name="joint_legs_1_left_leg_1_x4_1_dof_x4_p" actuator="joint_legs_1_left_leg_1_x4_1_dof_x4" user="13"/>
    <actuatorvel name="joint_legs_1_left_leg_1_x4_1_dof_x4_v" actuator="joint_legs_1_left_leg_1_x4_1_dof_x4" user="13"/>
    <actuatorfrc name="joint_legs_1_left_leg_1_x4_1_dof_x4_f" actuator="joint_legs_1_left_leg_1_x4_1_dof_x4" user="13" noise="0.001"/>
    
    <framequat name="orientation" objtype="site" noise="0.001" objname="imu"/>
    <gyro name="angular-velocity" site="imu" noise="0.005" cutoff="34.9"/>
  </sensor>
</mujoco>
