<?xml version='1.0' encoding='utf-8'?>
<mujoco model="robot_7dof_arm">
  <compiler angle="radian" meshdir="meshes" />
  <!-- If timestep is increased, iterations reduced, etc. PPO will find a 
	    to exploit the simulation and farm the healthy reward. Simulation
		stability matters a lot here. -->
	<option timestep="0.005" iterations="20" solver="Newton" noslip_iterations="5" integrator="RK4">
		<flag eulerdamp="enable" />
	</option>
  <default>
		<motor ctrlrange="-1 1" ctrllimited="true" gear="10" />
		<default class="visual">
			<geom type="mesh" condim="3" contype="0" conaffinity="0" group="2" />
		</default>
		<default class="collision">
			<geom type="capsule" friction=".7" mass="0" density="0" condim="3" contype="1" conaffinity="1" group="3" />
		</default>
	</default>
	<visual>
		<map force="0.1" zfar="30" />
		<rgba haze="0.15 0.25 0.35 1" />
		<global offwidth="2560" offheight="1440" elevation="-20" azimuth="120" />
	</visual>
  <asset>
    <mesh name="fused_component_upper_limb_assembly_7_dof_1_torso_1_top_skeleton_2_simple" file="fused_component_upper_limb_assembly_7_dof_1_torso_1_top_skeleton_2_simple.stl" />
    <mesh name="fused_component_upper_limb_assembly_7_dof_1_full_arm_7_dof_1_lower_arm_3_dof_1_hand_1_slide_2_simple" file="fused_component_upper_limb_assembly_7_dof_1_full_arm_7_dof_1_lower_arm_3_dof_1_hand_1_slide_2_simple.stl" />
    <mesh name="fused_component_upper_limb_assembly_7_dof_1_full_arm_7_dof_1_lower_arm_3_dof_1_hand_1_slide_1_simple" file="fused_component_upper_limb_assembly_7_dof_1_full_arm_7_dof_1_lower_arm_3_dof_1_hand_1_slide_1_simple.stl" />
    <mesh name="fused_component_upper_limb_assembly_7_dof_1_full_arm_7_dof_2_lower_arm_3_dof_1_hand_1_slide_2_simple" file="fused_component_upper_limb_assembly_7_dof_1_full_arm_7_dof_2_lower_arm_3_dof_1_hand_1_slide_2_simple.stl" />
    <mesh name="fused_component_upper_limb_assembly_7_dof_1_full_arm_7_dof_2_lower_arm_3_dof_1_hand_1_slide_1_simple" file="fused_component_upper_limb_assembly_7_dof_1_full_arm_7_dof_2_lower_arm_3_dof_1_hand_1_slide_1_simple.stl" />
    <mesh name="fused_component_upper_limb_assembly_7_dof_1_full_arm_7_dof_1_lower_arm_3_dof_1_rmd_x4_24_mock_3_inner_rmd_x4_24_1_simple" file="fused_component_upper_limb_assembly_7_dof_1_full_arm_7_dof_1_lower_arm_3_dof_1_rmd_x4_24_mock_3_inner_rmd_x4_24_1_simple.stl" />
    <mesh name="fused_component_upper_limb_assembly_7_dof_1_full_arm_7_dof_2_lower_arm_3_dof_1_rmd_x4_24_mock_3_inner_rmd_x4_24_1_simple" file="fused_component_upper_limb_assembly_7_dof_1_full_arm_7_dof_2_lower_arm_3_dof_1_rmd_x4_24_mock_3_inner_rmd_x4_24_1_simple.stl" />
    <mesh name="fused_component_lower_limbs_1_left_foot_1_rmd_x4_24_mock_1_inner_rmd_x4_24_1_simple" file="fused_component_lower_limbs_1_left_foot_1_rmd_x4_24_mock_1_inner_rmd_x4_24_1_simple.stl" />
    <mesh name="fused_component_lower_limbs_1_right_foot_1_rmd_x4_24_mock_1_inner_rmd_x4_24_1_simple" file="fused_component_lower_limbs_1_right_foot_1_rmd_x4_24_mock_1_inner_rmd_x4_24_1_simple.stl" />
    <mesh name="fused_component_lower_limbs_1_leg_assembly_1_rmd_x4_24_mock_1_outer_rmd_x4_24_1_simple" file="fused_component_lower_limbs_1_leg_assembly_1_rmd_x4_24_mock_1_outer_rmd_x4_24_1_simple.stl" />
    <mesh name="fused_component_lower_limbs_1_leg_assembly_2_rmd_x4_24_mock_1_outer_rmd_x4_24_1_simple" file="fused_component_lower_limbs_1_leg_assembly_2_rmd_x4_24_mock_1_outer_rmd_x4_24_1_simple.stl" />
    <mesh name="fused_component_upper_limb_assembly_7_dof_1_full_arm_7_dof_1_lower_arm_3_dof_1_rmd_x4_24_mock_2_inner_rmd_x4_24_1_simple" file="fused_component_upper_limb_assembly_7_dof_1_full_arm_7_dof_1_lower_arm_3_dof_1_rmd_x4_24_mock_2_inner_rmd_x4_24_1_simple.stl" />
    <mesh name="fused_component_upper_limb_assembly_7_dof_1_full_arm_7_dof_2_lower_arm_3_dof_1_rmd_x4_24_mock_2_inner_rmd_x4_24_1_simple" file="fused_component_upper_limb_assembly_7_dof_1_full_arm_7_dof_2_lower_arm_3_dof_1_rmd_x4_24_mock_2_inner_rmd_x4_24_1_simple.stl" />
    <mesh name="fused_component_lower_limbs_1_leg_assembly_1_rmd_x8_90_mock_3_inner_rmd_x8_90_1_simple" file="fused_component_lower_limbs_1_leg_assembly_1_rmd_x8_90_mock_3_inner_rmd_x8_90_1_simple.stl" />
    <mesh name="fused_component_upper_limb_assembly_7_dof_1_full_arm_7_dof_1_lower_arm_3_dof_1_rmd_x4_24_mock_1_outer_rmd_x4_24_1_simple" file="fused_component_upper_limb_assembly_7_dof_1_full_arm_7_dof_1_lower_arm_3_dof_1_rmd_x4_24_mock_1_outer_rmd_x4_24_1_simple.stl" />
    <mesh name="fused_component_upper_limb_assembly_7_dof_1_full_arm_7_dof_2_lower_arm_3_dof_1_rmd_x4_24_mock_1_outer_rmd_x4_24_1_simple" file="fused_component_upper_limb_assembly_7_dof_1_full_arm_7_dof_2_lower_arm_3_dof_1_rmd_x4_24_mock_1_outer_rmd_x4_24_1_simple.stl" />
    <mesh name="fused_component_lower_limbs_1_leg_assembly_2_rmd_x8_90_mock_3_inner_rmd_x8_90_1_simple" file="fused_component_lower_limbs_1_leg_assembly_2_rmd_x8_90_mock_3_inner_rmd_x8_90_1_simple.stl" />
    <mesh name="fused_component_lower_limbs_1_leg_assembly_1_rmd_x8_90_mock_2_inner_rmd_x8_90_1_simple" file="fused_component_lower_limbs_1_leg_assembly_1_rmd_x8_90_mock_2_inner_rmd_x8_90_1_simple.stl" />
    <mesh name="fused_component_upper_limb_assembly_7_dof_1_full_arm_7_dof_1_upper_left_arm_1_rmd_x4_24_mock_2_inner_rmd_x4_24_1_simple" file="fused_component_upper_limb_assembly_7_dof_1_full_arm_7_dof_1_upper_left_arm_1_rmd_x4_24_mock_2_inner_rmd_x4_24_1_simple.stl" />
    <mesh name="fused_component_upper_limb_assembly_7_dof_1_full_arm_7_dof_2_upper_left_arm_1_rmd_x4_24_mock_2_inner_rmd_x4_24_1_simple" file="fused_component_upper_limb_assembly_7_dof_1_full_arm_7_dof_2_upper_left_arm_1_rmd_x4_24_mock_2_inner_rmd_x4_24_1_simple.stl" />
    <mesh name="fused_component_lower_limbs_1_leg_assembly_2_rmd_x8_90_mock_2_inner_rmd_x8_90_1_simple" file="fused_component_lower_limbs_1_leg_assembly_2_rmd_x8_90_mock_2_inner_rmd_x8_90_1_simple.stl" />
    <mesh name="fused_component_lower_limbs_1_leg_assembly_1_rmd_x8_90_mock_1_inner_rmd_x8_90_1_simple" file="fused_component_lower_limbs_1_leg_assembly_1_rmd_x8_90_mock_1_inner_rmd_x8_90_1_simple.stl" />
    <mesh name="fused_component_upper_limb_assembly_7_dof_1_full_arm_7_dof_1_upper_left_arm_1_rmd_x4_24_mock_1_outer_rmd_x4_24_1_simple" file="fused_component_upper_limb_assembly_7_dof_1_full_arm_7_dof_1_upper_left_arm_1_rmd_x4_24_mock_1_outer_rmd_x4_24_1_simple.stl" />
    <mesh name="fused_component_upper_limb_assembly_7_dof_1_full_arm_7_dof_2_upper_left_arm_1_rmd_x4_24_mock_1_outer_rmd_x4_24_1_simple" file="fused_component_upper_limb_assembly_7_dof_1_full_arm_7_dof_2_upper_left_arm_1_rmd_x4_24_mock_1_outer_rmd_x4_24_1_simple.stl" />
    <mesh name="fused_component_lower_limbs_1_leg_assembly_2_rmd_x8_90_mock_1_inner_rmd_x8_90_1_simple" file="fused_component_lower_limbs_1_leg_assembly_2_rmd_x8_90_mock_1_inner_rmd_x8_90_1_simple.stl" />
    <mesh name="fused_component_lower_limbs_1_leg_assembly_1_rmd_x12_150_mock_1_inner_x12_150_1_simple" file="fused_component_lower_limbs_1_leg_assembly_1_rmd_x12_150_mock_1_inner_x12_150_1_simple.stl" />
    <mesh name="fused_component_lower_limbs_1_leg_assembly_2_rmd_x12_150_mock_1_inner_x12_150_1_simple" file="fused_component_lower_limbs_1_leg_assembly_2_rmd_x12_150_mock_1_inner_x12_150_1_simple.stl" />
    <mesh name="fused_component_upper_limb_assembly_7_dof_1_full_arm_7_dof_1_upper_left_arm_1_rmd_x8_90_mock_2_inner_rmd_x8_90_1_simple" file="fused_component_upper_limb_assembly_7_dof_1_full_arm_7_dof_1_upper_left_arm_1_rmd_x8_90_mock_2_inner_rmd_x8_90_1_simple.stl" />
    <mesh name="fused_component_upper_limb_assembly_7_dof_1_full_arm_7_dof_2_upper_left_arm_1_rmd_x8_90_mock_2_inner_rmd_x8_90_1_simple" file="fused_component_upper_limb_assembly_7_dof_1_full_arm_7_dof_2_upper_left_arm_1_rmd_x8_90_mock_2_inner_rmd_x8_90_1_simple.stl" />
    <mesh name="fused_component_upper_limb_assembly_7_dof_1_torso_1_rmd_x8_90_mock_1_inner_rmd_x8_90_1_simple" file="fused_component_upper_limb_assembly_7_dof_1_torso_1_rmd_x8_90_mock_1_inner_rmd_x8_90_1_simple.stl" />
    <mesh name="fused_component_upper_limb_assembly_7_dof_1_full_arm_7_dof_1_upper_left_arm_1_rmd_x8_90_mock_1_inner_rmd_x8_90_1_simple" file="fused_component_upper_limb_assembly_7_dof_1_full_arm_7_dof_1_upper_left_arm_1_rmd_x8_90_mock_1_inner_rmd_x8_90_1_simple.stl" />
    <mesh name="fused_component_upper_limb_assembly_7_dof_1_full_arm_7_dof_2_upper_left_arm_1_rmd_x8_90_mock_1_inner_rmd_x8_90_1_simple" file="fused_component_upper_limb_assembly_7_dof_1_full_arm_7_dof_2_upper_left_arm_1_rmd_x8_90_mock_1_inner_rmd_x8_90_1_simple.stl" />
    <texture name="grid" type="2d" builtin="checker" width="512" height="512" rgb1=".1 .2 .3" rgb2=".2 .3 .4" />
		<material name="grid" texture="grid" texrepeat="1 1" texuniform="true" reflectance=".2" />
  </asset>
  <worldbody>
    <geom name="floor" size="0 0 0.01" type="plane" material="grid" condim="3" />
		<light name="spotlight" mode="targetbodycom" target="root" diffuse=".8 .8 .8" specular="0.3 0.3 0.3" pos="0 -6 4" cutoff="30" />
    <body name="root" pos="0 0 1" quat="1 0 0 0"><geom type="mesh" rgba="0.64455 0.742648 0.801487 1" mesh="fused_component_upper_limb_assembly_7_dof_1_torso_1_top_skeleton_2_simple" />
      <camera name="front" pos="0 -3 1" xyaxes="1 0 0 0 1 2" mode="trackcom"/>
			<camera name="side" pos="-2.893 -1.330 1.257" xyaxes="0.405 -0.914 0.000 0.419 0.186 0.889" mode="trackcom"/>
      <freejoint name="root" />
    <body name="fused_component_upper_limb_assembly_7_dof_1_full_arm_7_dof_2_upper_left_arm_1_rmd_x8_90_mock_1_inner_rmd_x8_90_1" pos="0.151411 0.000437102 0.0219782" quat="0.566935 -0.422593 0.422593 -0.566935">
      <joint name="shoulder pitch" pos="0 0 0" axis="0 0 -1" range="-3.14159 3.14159" actuatorfrcrange="-80 80" />
      <geom type="mesh" rgba="0.71094 0.745901 0.822262 1" mesh="fused_component_upper_limb_assembly_7_dof_1_full_arm_7_dof_2_upper_left_arm_1_rmd_x8_90_mock_1_inner_rmd_x8_90_1_simple" />
      <body name="fused_component_upper_limb_assembly_7_dof_1_full_arm_7_dof_2_upper_left_arm_1_rmd_x8_90_mock_2_inner_rmd_x8_90_1" pos="-0.0197021 0.011375 0.087" quat="0.683013 -0.183013 -0.683013 -0.183013">
        <joint name="shoulder yaw" pos="0 0 0" axis="0 0 -1" range="0.977384 5.3058" actuatorfrcrange="-80 80" />
        <geom type="mesh" rgba="0.756258 0.749475 0.741439 1" mesh="fused_component_upper_limb_assembly_7_dof_1_full_arm_7_dof_2_upper_left_arm_1_rmd_x8_90_mock_2_inner_rmd_x8_90_1_simple" />
        <body name="fused_component_upper_limb_assembly_7_dof_1_full_arm_7_dof_2_upper_left_arm_1_rmd_x4_24_mock_1_outer_rmd_x4_24_1" pos="-0.1898 -1.96539e-09 -0.02275" quat="0.707107 1.64085e-08 -0.707107 1.64085e-08">
          <joint name="shoulder roll" pos="0 0 0" axis="0 0 -1" range="-3.14159 3.14159" actuatorfrcrange="-80 80" />
          <geom type="mesh" rgba="0.836582 0.836597 0.836605 1" mesh="fused_component_upper_limb_assembly_7_dof_1_full_arm_7_dof_2_upper_left_arm_1_rmd_x4_24_mock_1_outer_rmd_x4_24_1_simple" />
          <body name="fused_component_upper_limb_assembly_7_dof_1_full_arm_7_dof_2_upper_left_arm_1_rmd_x4_24_mock_2_inner_rmd_x4_24_1" pos="-2.94744e-10 0.009 0.134" quat="1.89469e-08 -1.89469e-08 -0.707107 0.707107">
            <joint name="elbow pitch" pos="0 0 0" axis="0 0 -1" range="1.44862 5.44543" actuatorfrcrange="-80 80" />
            <geom type="mesh" rgba="0.753073 0.754107 0.754694 1" mesh="fused_component_upper_limb_assembly_7_dof_1_full_arm_7_dof_2_upper_left_arm_1_rmd_x4_24_mock_2_inner_rmd_x4_24_1_simple" />
            <body name="fused_component_upper_limb_assembly_7_dof_1_full_arm_7_dof_2_lower_arm_3_dof_1_rmd_x4_24_mock_1_outer_rmd_x4_24_1" pos="0.0499362 0.156003 0.009" quat="0.109092 0.109092 0.698641 0.698641">
              <joint name="wrist roll" pos="0 0 0" axis="0 0 -1" range="-3.14159 3.14159" actuatorfrcrange="-80 80" />
              <geom type="mesh" rgba="0.85 0.85 0.85 1" mesh="fused_component_upper_limb_assembly_7_dof_1_full_arm_7_dof_2_lower_arm_3_dof_1_rmd_x4_24_mock_1_outer_rmd_x4_24_1_simple" />
              <body name="fused_component_upper_limb_assembly_7_dof_1_full_arm_7_dof_2_lower_arm_3_dof_1_rmd_x4_24_mock_2_inner_rmd_x4_24_1" pos="0.1135 -5.61782e-09 0.0895" quat="0.5 0.5 0.5 0.5">
                <joint name="wrist pitch" pos="0 0 0" axis="0 0 -1" range="-3.14159 3.14159" actuatorfrcrange="-80 80" />
                <geom type="mesh" rgba="0.812745 0.842157 0.858824 1" mesh="fused_component_upper_limb_assembly_7_dof_1_full_arm_7_dof_2_lower_arm_3_dof_1_rmd_x4_24_mock_2_inner_rmd_x4_24_1_simple" />
                <body name="fused_component_upper_limb_assembly_7_dof_1_full_arm_7_dof_2_lower_arm_3_dof_1_rmd_x4_24_mock_3_inner_rmd_x4_24_1" pos="-0.0985 2.6393e-09 -0.1135" quat="9.47343e-09 -0.707107 9.47343e-09 0.707107">
                  <joint name="wrist yaw" pos="0 0 0" axis="0 0 -1" range="-3.14159 3.14159" actuatorfrcrange="-80 80" />
                  <geom type="mesh" rgba="0.752673 0.753057 0.753287 1" mesh="fused_component_upper_limb_assembly_7_dof_1_full_arm_7_dof_2_lower_arm_3_dof_1_rmd_x4_24_mock_3_inner_rmd_x4_24_1_simple" />
                  <body name="fused_component_upper_limb_assembly_7_dof_1_full_arm_7_dof_2_lower_arm_3_dof_1_hand_1_slide_1" pos="0.0805 -0.1 -0.0985" quat="4.92255e-08 -4.92255e-08 -0.707107 0.707107">
                    <joint name="left hand right finger" pos="0 0 0" axis="0 0 -1" type="slide" range="0 0.051" actuatorfrcrange="-80 80" />
                    <geom type="mesh" rgba="0.493359 0.579282 0.748506 1" mesh="fused_component_upper_limb_assembly_7_dof_1_full_arm_7_dof_2_lower_arm_3_dof_1_hand_1_slide_1_simple" />
                  </body>
                  <body name="fused_component_upper_limb_assembly_7_dof_1_full_arm_7_dof_2_lower_arm_3_dof_1_hand_1_slide_2" pos="0.0805 0.1 -0.0985" quat="4.92255e-08 4.92255e-08 0.707107 0.707107">
                    <joint name="left hand left finger" pos="0 0 0" axis="0 0 -1" type="slide" range="-0.051 0" actuatorfrcrange="-80 80" />
                    <geom type="mesh" rgba="0.493359 0.579282 0.748506 1" mesh="fused_component_upper_limb_assembly_7_dof_1_full_arm_7_dof_2_lower_arm_3_dof_1_hand_1_slide_2_simple" />
                  </body>
                </body>
              </body>
            </body>
          </body>
        </body>
      </body>
    </body>
    <body name="fused_component_upper_limb_assembly_7_dof_1_full_arm_7_dof_1_upper_left_arm_1_rmd_x8_90_mock_1_inner_rmd_x8_90_1" pos="-0.151411 0.000437101 0.0219782" quat="0.566935 -0.422593 -0.422593 0.566935">
      <joint name="right shoulder pitch" pos="0 0 0" axis="0 0 -1" range="-3.14159 3.14159" actuatorfrcrange="-80 80" />
      <geom type="mesh" rgba="0.71094 0.745901 0.822262 1" mesh="fused_component_upper_limb_assembly_7_dof_1_full_arm_7_dof_1_upper_left_arm_1_rmd_x8_90_mock_1_inner_rmd_x8_90_1_simple" />
      <body name="fused_component_upper_limb_assembly_7_dof_1_full_arm_7_dof_1_upper_left_arm_1_rmd_x8_90_mock_2_inner_rmd_x8_90_1" pos="-0.0197021 0.011375 0.087" quat="0.683013 -0.183013 -0.683013 -0.183013">
        <joint name="right shoulder yaw" pos="0 0 0" axis="0 0 -1" range="0.977384 5.3058" actuatorfrcrange="-80 80" />
        <geom type="mesh" rgba="0.756258 0.749475 0.741439 1" mesh="fused_component_upper_limb_assembly_7_dof_1_full_arm_7_dof_1_upper_left_arm_1_rmd_x8_90_mock_2_inner_rmd_x8_90_1_simple" />
        <body name="fused_component_upper_limb_assembly_7_dof_1_full_arm_7_dof_1_upper_left_arm_1_rmd_x4_24_mock_1_outer_rmd_x4_24_1" pos="-0.1898 -1.96539e-09 -0.02275" quat="0.707107 1.64085e-08 -0.707107 1.64085e-08">
          <joint name="right shoulder roll" pos="0 0 0" axis="0 0 -1" range="-3.14159 3.14159" actuatorfrcrange="-80 80" />
          <geom type="mesh" rgba="0.836582 0.836597 0.836605 1" mesh="fused_component_upper_limb_assembly_7_dof_1_full_arm_7_dof_1_upper_left_arm_1_rmd_x4_24_mock_1_outer_rmd_x4_24_1_simple" />
          <body name="fused_component_upper_limb_assembly_7_dof_1_full_arm_7_dof_1_upper_left_arm_1_rmd_x4_24_mock_2_inner_rmd_x4_24_1" pos="-2.94744e-10 0.009 0.134" quat="1.89469e-08 -1.89469e-08 -0.707107 0.707107">
            <joint name="right elbow pitch" pos="0 0 0" axis="0 0 -1" range="1.44862 5.44543" actuatorfrcrange="-80 80" />
            <geom type="mesh" rgba="0.753073 0.754107 0.754694 1" mesh="fused_component_upper_limb_assembly_7_dof_1_full_arm_7_dof_1_upper_left_arm_1_rmd_x4_24_mock_2_inner_rmd_x4_24_1_simple" />
            <body name="fused_component_upper_limb_assembly_7_dof_1_full_arm_7_dof_1_lower_arm_3_dof_1_rmd_x4_24_mock_1_outer_rmd_x4_24_1" pos="0.0499362 0.156003 0.009" quat="0.109092 0.109092 0.698641 0.698641">
              <joint name="right wrist roll" pos="0 0 0" axis="0 0 -1" range="-3.14159 3.14159" actuatorfrcrange="-80 80" />
              <geom type="mesh" rgba="0.85 0.85 0.85 1" mesh="fused_component_upper_limb_assembly_7_dof_1_full_arm_7_dof_1_lower_arm_3_dof_1_rmd_x4_24_mock_1_outer_rmd_x4_24_1_simple" />
              <body name="fused_component_upper_limb_assembly_7_dof_1_full_arm_7_dof_1_lower_arm_3_dof_1_rmd_x4_24_mock_2_inner_rmd_x4_24_1" pos="0.1135 -5.61782e-09 0.0895" quat="0.5 0.5 0.5 0.5">
                <joint name="right wrist pitch" pos="0 0 0" axis="0 0 -1" range="-3.14159 3.14159" actuatorfrcrange="-80 80" />
                <geom type="mesh" rgba="0.812745 0.842157 0.858824 1" mesh="fused_component_upper_limb_assembly_7_dof_1_full_arm_7_dof_1_lower_arm_3_dof_1_rmd_x4_24_mock_2_inner_rmd_x4_24_1_simple" />
                <body name="fused_component_upper_limb_assembly_7_dof_1_full_arm_7_dof_1_lower_arm_3_dof_1_rmd_x4_24_mock_3_inner_rmd_x4_24_1" pos="-0.0985 2.6393e-09 -0.1135" quat="9.47343e-09 -0.707107 9.47343e-09 0.707107">
                  <joint name="right wrist yaw" pos="0 0 0" axis="0 0 -1" range="-3.14159 3.14159" actuatorfrcrange="-80 80" />
                  <geom type="mesh" rgba="0.752673 0.753057 0.753287 1" mesh="fused_component_upper_limb_assembly_7_dof_1_full_arm_7_dof_1_lower_arm_3_dof_1_rmd_x4_24_mock_3_inner_rmd_x4_24_1_simple" />
                  <body name="fused_component_upper_limb_assembly_7_dof_1_full_arm_7_dof_1_lower_arm_3_dof_1_hand_1_slide_1" pos="0.0805 -0.1 -0.0985" quat="4.92255e-08 -4.92255e-08 -0.707107 0.707107">
                    <joint name="right hand right finger" pos="0 0 0" axis="0 0 -1" type="slide" range="0 0.051" actuatorfrcrange="-80 80" />
                    <geom type="mesh" rgba="0.493359 0.579282 0.748506 1" mesh="fused_component_upper_limb_assembly_7_dof_1_full_arm_7_dof_1_lower_arm_3_dof_1_hand_1_slide_1_simple" />
                  </body>
                  <body name="fused_component_upper_limb_assembly_7_dof_1_full_arm_7_dof_1_lower_arm_3_dof_1_hand_1_slide_2" pos="0.0805 0.1 -0.0985" quat="4.92255e-08 4.92255e-08 0.707107 0.707107">
                    <joint name="right hand left finger" pos="0 0 0" axis="0 0 -1" type="slide" range="-0.051 0" actuatorfrcrange="-80 80" />
                    <geom type="mesh" rgba="0.493359 0.579282 0.748506 1" mesh="fused_component_upper_limb_assembly_7_dof_1_full_arm_7_dof_1_lower_arm_3_dof_1_hand_1_slide_2_simple" />
                  </body>
                </body>
              </body>
            </body>
          </body>
        </body>
      </body>
    </body>
    <body name="fused_component_upper_limb_assembly_7_dof_1_torso_1_rmd_x8_90_mock_1_inner_rmd_x8_90_1" pos="-2.34973e-08 0.000437101 -0.351562" quat="1.64085e-08 -0.707107 0.707107 -1.64085e-08">
      <joint name="torso roll" pos="0 0 0" axis="0 0 -1" range="-3.14159 3.14159" actuatorfrcrange="-80 80" />
      <geom type="mesh" rgba="0.231704 0.380579 0.705754 1" mesh="fused_component_upper_limb_assembly_7_dof_1_torso_1_rmd_x8_90_mock_1_inner_rmd_x8_90_1_simple" />
      <body name="fused_component_lower_limbs_1_leg_assembly_2_rmd_x12_150_mock_1_inner_x12_150_1" pos="0.02225 0.0385381 0.131" quat="0.612372 0.353553 -0.612372 0.353553">
        <joint name="left hip pitch" pos="0 0 0" axis="0 0 -1" range="-4.71239 4.71239" actuatorfrcrange="-80 80" />
        <geom type="mesh" rgba="0.688116 0.706616 0.747024 1" mesh="fused_component_lower_limbs_1_leg_assembly_2_rmd_x12_150_mock_1_inner_x12_150_1_simple" />
        <body name="fused_component_lower_limbs_1_leg_assembly_2_rmd_x8_90_mock_1_inner_rmd_x8_90_1" pos="-0.0244382 -0.000630373 -0.1015" quat="0.5 0.5 -0.5 -0.5">
          <joint name="left hip yaw" pos="0 0 0" axis="0 0 -1" range="-3.14159 3.14159" actuatorfrcrange="-80 80" />
          <geom type="mesh" rgba="0.8365 0.836517 0.836553 1" mesh="fused_component_lower_limbs_1_leg_assembly_2_rmd_x8_90_mock_1_inner_rmd_x8_90_1_simple" />
          <body name="fused_component_lower_limbs_1_leg_assembly_2_rmd_x8_90_mock_2_inner_rmd_x8_90_1" pos="-0.07875 -0.136399 -0.01965" quat="0.683013 0.683013 -0.183013 -0.183013">
            <joint name="left hip roll" pos="0 0 0" axis="0 0 -1" range="-3.14159 3.14159" actuatorfrcrange="-80 80" />
            <geom type="mesh" rgba="0.685312 0.687559 0.692465 1" mesh="fused_component_lower_limbs_1_leg_assembly_2_rmd_x8_90_mock_2_inner_rmd_x8_90_1_simple" />
            <body name="fused_component_lower_limbs_1_leg_assembly_2_rmd_x8_90_mock_3_inner_rmd_x8_90_1" pos="6.61991e-09 0.02065 0.127" quat="0.5 -0.5 0.5 0.5">
              <joint name="left knee pitch" pos="0 0 0" axis="0 0 -1" range="-3.14159 3.14159" actuatorfrcrange="-80 80" />
              <geom type="mesh" rgba="0.753371 0.754689 0.755183 1" mesh="fused_component_lower_limbs_1_leg_assembly_2_rmd_x8_90_mock_3_inner_rmd_x8_90_1_simple" />
              <body name="fused_component_lower_limbs_1_leg_assembly_2_rmd_x4_24_mock_1_outer_rmd_x4_24_1" pos="0.123 -0.213042 -0.0129" quat="2.60501e-08 -0.104528 0.994522 -3.67176e-08">
                <joint name="left ankle pitch" pos="0 0 0" axis="0 0 -1" range="-3.14159 3.14159" actuatorfrcrange="-80 80" />
                <geom type="mesh" rgba="0.753102 0.753102 0.753103 1" mesh="fused_component_lower_limbs_1_leg_assembly_2_rmd_x4_24_mock_1_outer_rmd_x4_24_1_simple" />
                <body name="fused_component_lower_limbs_1_right_foot_1_rmd_x4_24_mock_1_inner_rmd_x4_24_1" pos="-0.0135 -0.07155 0.01055" quat="0.5 0.5 0.5 0.5">
                  <joint name="left ankle roll" pos="0 0 0" axis="0 0 -1" range="-3.14159 3.14159" actuatorfrcrange="-80 80" />
                  <geom type="mesh" rgba="0.795129 0.603707 0.375245 1" mesh="fused_component_lower_limbs_1_right_foot_1_rmd_x4_24_mock_1_inner_rmd_x4_24_1_simple" />
                </body>
              </body>
            </body>
          </body>
        </body>
      </body>
      <body name="fused_component_lower_limbs_1_leg_assembly_1_rmd_x12_150_mock_1_inner_x12_150_1" pos="-0.02225 -0.0385381 0.131" quat="0.353553 -0.612372 -0.353553 -0.612372">
        <joint name="right hip pitch" pos="0 0 0" axis="0 0 -1" range="-4.71239 4.71239" actuatorfrcrange="-80 80" />
        <geom type="mesh" rgba="0.688116 0.706616 0.747024 1" mesh="fused_component_lower_limbs_1_leg_assembly_1_rmd_x12_150_mock_1_inner_x12_150_1_simple" />
        <body name="fused_component_lower_limbs_1_leg_assembly_1_rmd_x8_90_mock_1_inner_rmd_x8_90_1" pos="-0.0244382 -0.000630373 -0.1015" quat="0.5 0.5 -0.5 -0.5">
          <joint name="right hip yaw" pos="0 0 0" axis="0 0 -1" range="-3.14159 3.14159" actuatorfrcrange="-80 80" />
          <geom type="mesh" rgba="0.8365 0.836517 0.836553 1" mesh="fused_component_lower_limbs_1_leg_assembly_1_rmd_x8_90_mock_1_inner_rmd_x8_90_1_simple" />
          <body name="fused_component_lower_limbs_1_leg_assembly_1_rmd_x8_90_mock_2_inner_rmd_x8_90_1" pos="-0.07875 -0.136399 -0.01965" quat="0.683013 0.683013 -0.183013 -0.183013">
            <joint name="right hip roll" pos="0 0 0" axis="0 0 -1" range="-3.14159 3.14159" actuatorfrcrange="-80 80" />
            <geom type="mesh" rgba="0.685312 0.687559 0.692465 1" mesh="fused_component_lower_limbs_1_leg_assembly_1_rmd_x8_90_mock_2_inner_rmd_x8_90_1_simple" />
            <body name="fused_component_lower_limbs_1_leg_assembly_1_rmd_x8_90_mock_3_inner_rmd_x8_90_1" pos="6.61991e-09 0.02065 0.127" quat="0.5 -0.5 0.5 0.5">
              <joint name="right knee pitch" pos="0 0 0" axis="0 0 -1" range="-3.14159 3.14159" actuatorfrcrange="-80 80" />
              <geom type="mesh" rgba="0.753371 0.754689 0.755183 1" mesh="fused_component_lower_limbs_1_leg_assembly_1_rmd_x8_90_mock_3_inner_rmd_x8_90_1_simple" />
              <body name="fused_component_lower_limbs_1_leg_assembly_1_rmd_x4_24_mock_1_outer_rmd_x4_24_1" pos="0.123 -0.213042 -0.0129" quat="2.60501e-08 -0.104528 0.994522 -3.67176e-08">
                <joint name="right ankle pitch" pos="0 0 0" axis="0 0 -1" range="-3.14159 3.14159" actuatorfrcrange="-80 80" />
                <geom type="mesh" rgba="0.794118 0.794122 0.794124 1" mesh="fused_component_lower_limbs_1_leg_assembly_1_rmd_x4_24_mock_1_outer_rmd_x4_24_1_simple" />
                <body name="fused_component_lower_limbs_1_left_foot_1_rmd_x4_24_mock_1_inner_rmd_x4_24_1" pos="0.0135 -0.07155 0.01055" quat="0.5 -0.5 -0.5 0.5">
                  <joint name="right ankle roll" pos="0 0 0" axis="0 0 -1" range="-3.14159 3.14159" actuatorfrcrange="-80 80" />
                  <geom type="mesh" rgba="0.942494 0.5572 0.0988358 1" mesh="fused_component_lower_limbs_1_left_foot_1_rmd_x4_24_mock_1_inner_rmd_x4_24_1_simple" />
                </body>
              </body>
            </body>
          </body>
        </body>
      </body>
    </body>
  </body></worldbody>
  <actuator>
    <!-- Actuators for left leg joints -->
    <motor name="left_hip_pitch_motor" joint="left hip pitch" />
    <motor name="left_hip_yaw_motor" joint="left hip yaw" />
    <motor name="left_hip_roll_motor" joint="left hip roll" />
    <motor name="left_knee_pitch_motor" joint="left knee pitch" />
    <motor name="left_ankle_pitch_motor" joint="left ankle pitch" />
    <motor name="left_ankle_roll_motor" joint="left ankle roll" />

    <!-- Actuators for right leg joints -->
    <motor name="right_hip_pitch_motor" joint="right hip pitch" />
    <motor name="right_hip_yaw_motor" joint="right hip yaw" />
    <motor name="right_hip_roll_motor" joint="right hip roll" />
    <motor name="right_knee_pitch_motor" joint="right knee pitch" />
    <motor name="right_ankle_pitch_motor" joint="right ankle pitch" />
    <motor name="right_ankle_roll_motor" joint="right ankle roll" />
  </actuator>
  <keyframe>
    <key name="default" qpos='0.0 -0.126 2.12 1.89 -1.13 2.1 -1.23 0.0 0.0 0.0 0.0 -0.346 -0.251 0.377 -3.14 -0.437 0.911 -1.55 1.46 1.45 2.17 0.238 1.79 1.55 -1.67 1.04 2.01 0.44 1.79 0.0 0.0 0.0 0.0 0.0 0.0 0.0 0.0 0.0'/>
  </keyframe>

</mujoco>